2025-03-01 23:30:03,771 INFO     21 task_executor_0 log path: /ragflow/logs/task_executor_0.log, log levels: {'peewee': 'WARNING', 'pdfminer': 'WARNING', 'root': 'INFO'}
2025-03-01 23:30:04,333 INFO     21 init database on cluster mode successfully
2025-03-01 23:30:18,272 INFO     21 TextRecognizer det uses CPU
2025-03-01 23:30:18,436 INFO     21 TextRecognizer rec uses CPU
2025-03-01 23:30:18,484 INFO     21 
  ______           __      ______                     __            
 /_  __/___ ______/ /__   / ____/  _____  _______  __/ /_____  _____
  / / / __ `/ ___/ //_/  / __/ | |/_/ _ \/ ___/ / / / __/ __ \/ ___/
 / / / /_/ (__  ) ,<    / /____>  </  __/ /__/ /_/ / /_/ /_/ / /    
/_/  \__,_/____/_/|_|  /_____/_/|_|\___/\___/\__,_/\__/\____/_/                               
    
2025-03-01 23:30:18,485 INFO     21 TaskExecutor: RAGFlow version: v0.16.0 slim
2025-03-01 23:30:18,485 INFO     21 Use Elasticsearch http://es01:9200 as the doc engine.
2025-03-01 23:30:18,498 INFO     21 GET http://es01:9200/ [status:200 duration:0.010s]
2025-03-01 23:30:18,502 INFO     21 HEAD http://es01:9200/ [status:200 duration:0.003s]
2025-03-01 23:30:18,503 INFO     21 Elasticsearch http://es01:9200 is healthy.
2025-03-01 23:30:18,516 WARNING  21 Load term.freq FAIL!
2025-03-01 23:30:18,525 WARNING  21 Realtime synonym is disabled, since no redis connection.
2025-03-01 23:30:18,536 WARNING  21 Load term.freq FAIL!
2025-03-01 23:30:18,544 WARNING  21 Realtime synonym is disabled, since no redis connection.
2025-03-01 23:30:18,544 INFO     21 MAX_CONTENT_LENGTH: 134217728
2025-03-01 23:30:18,544 INFO     21 SERVER_QUEUE_MAX_LEN: 1024
2025-03-01 23:30:18,544 INFO     21 SERVER_QUEUE_RETENTION: 3600
2025-03-01 23:30:18,544 INFO     21 MAX_FILE_COUNT_PER_USER: 0
2025-03-01 23:30:18,547 WARNING  21 RedisDB.queue_info rag_flow_svr_queue got exception: no such key
2025-03-01 23:30:18,548 INFO     21 task_consumer_0 reported heartbeat: {"name": "task_consumer_0", "now": "2025-03-01T23:30:18.547+08:00", "boot_at": "2025-03-01T23:30:18.484+08:00", "pending": 0, "lag": 0, "done": 0, "failed": 0, "current": null}
2025-03-01 23:30:48,578 WARNING  21 RedisDB.queue_info rag_flow_svr_queue got exception: no such key
2025-03-01 23:30:48,579 INFO     21 task_consumer_0 reported heartbeat: {"name": "task_consumer_0", "now": "2025-03-01T23:30:48.577+08:00", "boot_at": "2025-03-01T23:30:18.484+08:00", "pending": 0, "lag": 0, "done": 0, "failed": 0, "current": null}
2025-03-01 23:31:08,646 ERROR    21 RedisDB.get_unacked_for task_consumer_0 got exception: Error -2 connecting to redis:6379. Name or service not known.
Traceback (most recent call last):
  File "/ragflow/.venv/lib/python3.10/site-packages/valkey/connection.py", line 1116, in get_connection
    if connection.can_read() and connection.client_cache is None:
  File "/ragflow/.venv/lib/python3.10/site-packages/valkey/connection.py", line 524, in can_read
    return self._parser.can_read(timeout)
  File "/ragflow/.venv/lib/python3.10/site-packages/valkey/_parsers/base.py", line 128, in can_read
    return self._buffer and self._buffer.can_read(timeout)
  File "/ragflow/.venv/lib/python3.10/site-packages/valkey/_parsers/socket.py", line 95, in can_read
    return bool(self.unread_bytes()) or self._read_from_socket(
  File "/ragflow/.venv/lib/python3.10/site-packages/valkey/_parsers/socket.py", line 68, in _read_from_socket
    raise ConnectionError(SERVER_CLOSED_CONNECTION_ERROR)
valkey.exceptions.ConnectionError: Connection closed by server.

During handling of the above exception, another exception occurred:

Traceback (most recent call last):
  File "/ragflow/.venv/lib/python3.10/site-packages/valkey/connection.py", line 302, in connect
    sock = self.retry.call_with_retry(
  File "/ragflow/.venv/lib/python3.10/site-packages/valkey/retry.py", line 62, in call_with_retry
    return do()
  File "/ragflow/.venv/lib/python3.10/site-packages/valkey/connection.py", line 303, in <lambda>
    lambda: self._connect(), lambda error: self.disconnect(error)
  File "/ragflow/.venv/lib/python3.10/site-packages/valkey/connection.py", line 696, in _connect
    for res in socket.getaddrinfo(
  File "/usr/lib/python3.10/socket.py", line 955, in getaddrinfo
    for res in _socket.getaddrinfo(host, port, family, type, proto, flags):
socket.gaierror: [Errno -2] Name or service not known

During handling of the above exception, another exception occurred:

Traceback (most recent call last):
  File "/ragflow/rag/utils/redis_conn.py", line 244, in get_unacked_for
    group_info = self.REDIS.xinfo_groups(queue_name)
  File "/ragflow/.venv/lib/python3.10/site-packages/valkey/commands/core.py", line 3810, in xinfo_groups
    return self.execute_command("XINFO GROUPS", name)
  File "/ragflow/.venv/lib/python3.10/site-packages/valkey/client.py", line 564, in execute_command
    conn = self.connection or pool.get_connection(command_name, **options)
  File "/ragflow/.venv/lib/python3.10/site-packages/valkey/connection.py", line 1120, in get_connection
    connection.connect()
  File "/ragflow/.venv/lib/python3.10/site-packages/valkey/connection.py", line 308, in connect
    raise ConnectionError(self._error_message(e))
valkey.exceptions.ConnectionError: Error -2 connecting to redis:6379. Name or service not known.
2025-03-01 23:31:08,686 ERROR    21 RedisDB.queue_consumer rag_flow_svr_queue got exception: Error -2 connecting to redis:6379. Name or service not known.
Traceback (most recent call last):
  File "/ragflow/.venv/lib/python3.10/site-packages/valkey/connection.py", line 302, in connect
    sock = self.retry.call_with_retry(
  File "/ragflow/.venv/lib/python3.10/site-packages/valkey/retry.py", line 62, in call_with_retry
    return do()
  File "/ragflow/.venv/lib/python3.10/site-packages/valkey/connection.py", line 303, in <lambda>
    lambda: self._connect(), lambda error: self.disconnect(error)
  File "/ragflow/.venv/lib/python3.10/site-packages/valkey/connection.py", line 696, in _connect
    for res in socket.getaddrinfo(
  File "/usr/lib/python3.10/socket.py", line 955, in getaddrinfo
    for res in _socket.getaddrinfo(host, port, family, type, proto, flags):
socket.gaierror: [Errno -2] Name or service not known

During handling of the above exception, another exception occurred:

Traceback (most recent call last):
  File "/ragflow/rag/utils/redis_conn.py", line 213, in queue_consumer
    group_info = self.REDIS.xinfo_groups(queue_name)
  File "/ragflow/.venv/lib/python3.10/site-packages/valkey/commands/core.py", line 3810, in xinfo_groups
    return self.execute_command("XINFO GROUPS", name)
  File "/ragflow/.venv/lib/python3.10/site-packages/valkey/client.py", line 564, in execute_command
    conn = self.connection or pool.get_connection(command_name, **options)
  File "/ragflow/.venv/lib/python3.10/site-packages/valkey/connection.py", line 1107, in get_connection
    connection.connect()
  File "/ragflow/.venv/lib/python3.10/site-packages/valkey/connection.py", line 308, in connect
    raise ConnectionError(self._error_message(e))
valkey.exceptions.ConnectionError: Error -2 connecting to redis:6379. Name or service not known.
2025-03-01 23:31:13,968 ERROR    21 RedisDB.get_unacked_for task_consumer_0 got exception: Error -2 connecting to redis:6379. Name or service not known.
Traceback (most recent call last):
  File "/ragflow/.venv/lib/python3.10/site-packages/valkey/connection.py", line 302, in connect
    sock = self.retry.call_with_retry(
  File "/ragflow/.venv/lib/python3.10/site-packages/valkey/retry.py", line 62, in call_with_retry
    return do()
  File "/ragflow/.venv/lib/python3.10/site-packages/valkey/connection.py", line 303, in <lambda>
    lambda: self._connect(), lambda error: self.disconnect(error)
  File "/ragflow/.venv/lib/python3.10/site-packages/valkey/connection.py", line 696, in _connect
    for res in socket.getaddrinfo(
  File "/usr/lib/python3.10/socket.py", line 955, in getaddrinfo
    for res in _socket.getaddrinfo(host, port, family, type, proto, flags):
socket.gaierror: [Errno -2] Name or service not known

During handling of the above exception, another exception occurred:

Traceback (most recent call last):
  File "/ragflow/rag/utils/redis_conn.py", line 244, in get_unacked_for
    group_info = self.REDIS.xinfo_groups(queue_name)
  File "/ragflow/.venv/lib/python3.10/site-packages/valkey/commands/core.py", line 3810, in xinfo_groups
    return self.execute_command("XINFO GROUPS", name)
  File "/ragflow/.venv/lib/python3.10/site-packages/valkey/client.py", line 564, in execute_command
    conn = self.connection or pool.get_connection(command_name, **options)
  File "/ragflow/.venv/lib/python3.10/site-packages/valkey/connection.py", line 1107, in get_connection
    connection.connect()
  File "/ragflow/.venv/lib/python3.10/site-packages/valkey/connection.py", line 308, in connect
    raise ConnectionError(self._error_message(e))
valkey.exceptions.ConnectionError: Error -2 connecting to redis:6379. Name or service not known.
2025-03-01 23:31:14,011 ERROR    21 RedisDB.queue_consumer rag_flow_svr_queue got exception: Error -2 connecting to redis:6379. Name or service not known.
Traceback (most recent call last):
  File "/ragflow/.venv/lib/python3.10/site-packages/valkey/connection.py", line 302, in connect
    sock = self.retry.call_with_retry(
  File "/ragflow/.venv/lib/python3.10/site-packages/valkey/retry.py", line 62, in call_with_retry
    return do()
  File "/ragflow/.venv/lib/python3.10/site-packages/valkey/connection.py", line 303, in <lambda>
    lambda: self._connect(), lambda error: self.disconnect(error)
  File "/ragflow/.venv/lib/python3.10/site-packages/valkey/connection.py", line 696, in _connect
    for res in socket.getaddrinfo(
  File "/usr/lib/python3.10/socket.py", line 955, in getaddrinfo
    for res in _socket.getaddrinfo(host, port, family, type, proto, flags):
socket.gaierror: [Errno -2] Name or service not known

During handling of the above exception, another exception occurred:

Traceback (most recent call last):
  File "/ragflow/rag/utils/redis_conn.py", line 213, in queue_consumer
    group_info = self.REDIS.xinfo_groups(queue_name)
  File "/ragflow/.venv/lib/python3.10/site-packages/valkey/commands/core.py", line 3810, in xinfo_groups
    return self.execute_command("XINFO GROUPS", name)
  File "/ragflow/.venv/lib/python3.10/site-packages/valkey/client.py", line 564, in execute_command
    conn = self.connection or pool.get_connection(command_name, **options)
  File "/ragflow/.venv/lib/python3.10/site-packages/valkey/connection.py", line 1107, in get_connection
    connection.connect()
  File "/ragflow/.venv/lib/python3.10/site-packages/valkey/connection.py", line 308, in connect
    raise ConnectionError(self._error_message(e))
valkey.exceptions.ConnectionError: Error -2 connecting to redis:6379. Name or service not known.
2025-03-01 23:31:15,057 ERROR    21 RedisDB.get_unacked_for task_consumer_0 got exception: Error -2 connecting to redis:6379. Name or service not known.
Traceback (most recent call last):
  File "/ragflow/.venv/lib/python3.10/site-packages/valkey/connection.py", line 302, in connect
    sock = self.retry.call_with_retry(
  File "/ragflow/.venv/lib/python3.10/site-packages/valkey/retry.py", line 62, in call_with_retry
    return do()
  File "/ragflow/.venv/lib/python3.10/site-packages/valkey/connection.py", line 303, in <lambda>
    lambda: self._connect(), lambda error: self.disconnect(error)
  File "/ragflow/.venv/lib/python3.10/site-packages/valkey/connection.py", line 696, in _connect
    for res in socket.getaddrinfo(
  File "/usr/lib/python3.10/socket.py", line 955, in getaddrinfo
    for res in _socket.getaddrinfo(host, port, family, type, proto, flags):
socket.gaierror: [Errno -2] Name or service not known

During handling of the above exception, another exception occurred:

Traceback (most recent call last):
  File "/ragflow/rag/utils/redis_conn.py", line 244, in get_unacked_for
    group_info = self.REDIS.xinfo_groups(queue_name)
  File "/ragflow/.venv/lib/python3.10/site-packages/valkey/commands/core.py", line 3810, in xinfo_groups
    return self.execute_command("XINFO GROUPS", name)
  File "/ragflow/.venv/lib/python3.10/site-packages/valkey/client.py", line 564, in execute_command
    conn = self.connection or pool.get_connection(command_name, **options)
  File "/ragflow/.venv/lib/python3.10/site-packages/valkey/connection.py", line 1107, in get_connection
    connection.connect()
  File "/ragflow/.venv/lib/python3.10/site-packages/valkey/connection.py", line 308, in connect
    raise ConnectionError(self._error_message(e))
valkey.exceptions.ConnectionError: Error -2 connecting to redis:6379. Name or service not known.
2025-03-01 23:31:15,088 ERROR    21 RedisDB.queue_consumer rag_flow_svr_queue got exception: Error -2 connecting to redis:6379. Name or service not known.
Traceback (most recent call last):
  File "/ragflow/.venv/lib/python3.10/site-packages/valkey/connection.py", line 302, in connect
    sock = self.retry.call_with_retry(
  File "/ragflow/.venv/lib/python3.10/site-packages/valkey/retry.py", line 62, in call_with_retry
    return do()
  File "/ragflow/.venv/lib/python3.10/site-packages/valkey/connection.py", line 303, in <lambda>
    lambda: self._connect(), lambda error: self.disconnect(error)
  File "/ragflow/.venv/lib/python3.10/site-packages/valkey/connection.py", line 696, in _connect
    for res in socket.getaddrinfo(
  File "/usr/lib/python3.10/socket.py", line 955, in getaddrinfo
    for res in _socket.getaddrinfo(host, port, family, type, proto, flags):
socket.gaierror: [Errno -2] Name or service not known

During handling of the above exception, another exception occurred:

Traceback (most recent call last):
  File "/ragflow/rag/utils/redis_conn.py", line 213, in queue_consumer
    group_info = self.REDIS.xinfo_groups(queue_name)
  File "/ragflow/.venv/lib/python3.10/site-packages/valkey/commands/core.py", line 3810, in xinfo_groups
    return self.execute_command("XINFO GROUPS", name)
  File "/ragflow/.venv/lib/python3.10/site-packages/valkey/client.py", line 564, in execute_command
    conn = self.connection or pool.get_connection(command_name, **options)
  File "/ragflow/.venv/lib/python3.10/site-packages/valkey/connection.py", line 1107, in get_connection
    connection.connect()
  File "/ragflow/.venv/lib/python3.10/site-packages/valkey/connection.py", line 308, in connect
    raise ConnectionError(self._error_message(e))
valkey.exceptions.ConnectionError: Error -2 connecting to redis:6379. Name or service not known.
2025-03-01 23:31:16,131 ERROR    21 RedisDB.get_unacked_for task_consumer_0 got exception: Error -2 connecting to redis:6379. Name or service not known.
Traceback (most recent call last):
  File "/ragflow/.venv/lib/python3.10/site-packages/valkey/connection.py", line 302, in connect
    sock = self.retry.call_with_retry(
  File "/ragflow/.venv/lib/python3.10/site-packages/valkey/retry.py", line 62, in call_with_retry
    return do()
  File "/ragflow/.venv/lib/python3.10/site-packages/valkey/connection.py", line 303, in <lambda>
    lambda: self._connect(), lambda error: self.disconnect(error)
  File "/ragflow/.venv/lib/python3.10/site-packages/valkey/connection.py", line 696, in _connect
    for res in socket.getaddrinfo(
  File "/usr/lib/python3.10/socket.py", line 955, in getaddrinfo
    for res in _socket.getaddrinfo(host, port, family, type, proto, flags):
socket.gaierror: [Errno -2] Name or service not known

During handling of the above exception, another exception occurred:

Traceback (most recent call last):
  File "/ragflow/rag/utils/redis_conn.py", line 244, in get_unacked_for
    group_info = self.REDIS.xinfo_groups(queue_name)
  File "/ragflow/.venv/lib/python3.10/site-packages/valkey/commands/core.py", line 3810, in xinfo_groups
    return self.execute_command("XINFO GROUPS", name)
  File "/ragflow/.venv/lib/python3.10/site-packages/valkey/client.py", line 564, in execute_command
    conn = self.connection or pool.get_connection(command_name, **options)
  File "/ragflow/.venv/lib/python3.10/site-packages/valkey/connection.py", line 1107, in get_connection
    connection.connect()
  File "/ragflow/.venv/lib/python3.10/site-packages/valkey/connection.py", line 308, in connect
    raise ConnectionError(self._error_message(e))
valkey.exceptions.ConnectionError: Error -2 connecting to redis:6379. Name or service not known.
2025-03-01 23:31:16,172 ERROR    21 RedisDB.queue_consumer rag_flow_svr_queue got exception: Error -2 connecting to redis:6379. Name or service not known.
Traceback (most recent call last):
  File "/ragflow/.venv/lib/python3.10/site-packages/valkey/connection.py", line 302, in connect
    sock = self.retry.call_with_retry(
  File "/ragflow/.venv/lib/python3.10/site-packages/valkey/retry.py", line 62, in call_with_retry
    return do()
  File "/ragflow/.venv/lib/python3.10/site-packages/valkey/connection.py", line 303, in <lambda>
    lambda: self._connect(), lambda error: self.disconnect(error)
  File "/ragflow/.venv/lib/python3.10/site-packages/valkey/connection.py", line 696, in _connect
    for res in socket.getaddrinfo(
  File "/usr/lib/python3.10/socket.py", line 955, in getaddrinfo
    for res in _socket.getaddrinfo(host, port, family, type, proto, flags):
socket.gaierror: [Errno -2] Name or service not known

During handling of the above exception, another exception occurred:

Traceback (most recent call last):
  File "/ragflow/rag/utils/redis_conn.py", line 213, in queue_consumer
    group_info = self.REDIS.xinfo_groups(queue_name)
  File "/ragflow/.venv/lib/python3.10/site-packages/valkey/commands/core.py", line 3810, in xinfo_groups
    return self.execute_command("XINFO GROUPS", name)
  File "/ragflow/.venv/lib/python3.10/site-packages/valkey/client.py", line 564, in execute_command
    conn = self.connection or pool.get_connection(command_name, **options)
  File "/ragflow/.venv/lib/python3.10/site-packages/valkey/connection.py", line 1107, in get_connection
    connection.connect()
  File "/ragflow/.venv/lib/python3.10/site-packages/valkey/connection.py", line 308, in connect
    raise ConnectionError(self._error_message(e))
valkey.exceptions.ConnectionError: Error -2 connecting to redis:6379. Name or service not known.
